Workbook

Sheet All_TVs
A1: product_id | B1: product_name | C1: product_brand | D1: category | E1: price | F1: rating | G1: rating_count | H1: product_link | I1: smart_feature | J1: screen_size_inch | K1: store | L1: Smart_TV | M1: size_segment | N1: Avergae_Brand_Price | O1: Price_Difference_A_vs_W | P1: Best_Deal_Label
A2: TVPROD0000 | B2: Philips 43" 8K UHD Smart LED TV with Tizen | C2: Philips | D2: TV | E2: 320.17 | F2: 4.3 | G2: 1983 | H2: https://www.amazon.com/dp/TVPROD0000 | I2: No | J2: 43 | K2: Amazon | L2: no | M2: Medium | N2: =AVERAGEIF(C:C, C2, E:E) -> 1103.4574 | O2: =E2 - N2 -> -783.28743 | P2: =IF(E2=_xlfn.MINIFS(E:E, B:B, B2), "Best Deal", "") -> Best Deal
A3: TVPROD0001 | B3: Philips 48" 4K UHD Smart LED TV with Fire TV | C3: Philips | D3: TV | E3: 910.02 | F3: 4.5 | G3: 9568 | H3: https://www.amazon.com/dp/TVPROD0001 | I3: No | J3: 48 | K3: Amazon | L3: no | M3: Medium | N3: =AVERAGEIF(C:C, C3, E:E) -> 1103.4574 | O3: =E3 - N3 -> -193.43743 | P3: =IF(E3=_xlfn.MINIFS(E:E, B:B, B3), "Best Deal", "") -> Best Deal
A4: TVPROD0002 | B4: Vizio 40" HD Smart LED TV with Fire TV | C4: Vizio | D4: TV | E4: 632.41 | F4: 4.9 | G4: 692 | H4: https://www.amazon.com/dp/TVPROD0002 | I4: No | J4: 40 | K4: Amazon | L4: no | M4: Medium | N4: =AVERAGEIF(C:C, C4, E:E) -> 1147.5588 | O4: =E4 - N4 -> -515.14883 | P4: =IF(E4=_xlfn.MINIFS(E:E, B:B, B4), "Best Deal", "") -> Best Deal | S4: Average of price | T4: Column Labels
A5: TVPROD0003 | B5: Insignia 70" Full HD Smart LED TV with Roku | C5: Insignia | D5: TV | E5: 839.65 | F5: 4.7 | G5: 4975 | H5: https://www.amazon.com/dp/TVPROD0003 | I5: No | J5: 70 | K5: Amazon | L5: no | M5: Large | N5: =AVERAGEIF(C:C, C5, E:E) -> 733.32533 | O5: =E5 - N5 -> 106.32467 | P5: =IF(E5=_xlfn.MINIFS(E:E, B:B, B5), "Best Deal", "") -> Best Deal | S5: Row Labels | T5: Amazon | U5: eBay | V5: Target | W5: Walmart | X5: (blank) | Y5: Grand Total
A6: TVPROD0004 | B6: Samsung 55" 4K UHD Smart LED TV with Fire TV | C6: Samsung | D6: TV | E6: 1051.04 | F6: 4.2 | G6: 7315 | H6: https://www.amazon.com/dp/TVPROD0004 | I6: Yes | J6: 55 | K6: Amazon | L6: yes | M6: Medium | N6: =AVERAGEIF(C:C, C6, E:E) -> 1136.2494 | O6: =E6 - N6 -> -85.209363 | P6: =IF(E6=_xlfn.MINIFS(E:E, B:B, B6), "Best Deal", "") -> Best Deal | S6: Hisense | T6: 801.87138 | U6: 1094.1205 | W6: 1328.2846 | Y6: 1177.9799
A7: TVPROD0005 | B7: Philips 85" 4K UHD Smart LED TV with WebOS | C7: Philips | D7: TV | E7: 1179.7 | F7: 4.4 | G7: 301 | H7: https://www.amazon.com/dp/TVPROD0005 | I7: Yes | J7: 85 | K7: Amazon | L7: yes | M7: Large | N7: =AVERAGEIF(C:C, C7, E:E) -> 1103.4574 | O7: =E7 - N7 -> 76.242574 | P7: =IF(E7=_xlfn.MINIFS(E:E, B:B, B7), "Best Deal", "") -> Best Deal | S7: Large | T7: 1029.195 | U7: 1093.0004 | W7: 1312.3443 | Y7: 1201.0036
A8: TVPROD0006 | B8: Insignia 24" HD Smart LED TV with Roku | C8: Insignia | D8: TV | E8: 297.26 | F8: 4.3 | G8: 554 | H8: https://www.amazon.com/dp/TVPROD0006 | I8: Yes | J8: 24 | K8: Amazon | L8: yes | M8: Small | N8: =AVERAGEIF(C:C, C8, E:E) -> 733.32533 | O8: =E8 - N8 -> -436.06533 | P8: =IF(E8=_xlfn.MINIFS(E:E, B:B, B8), "Best Deal", "") -> Best Deal | S8: Medium | T8: 582.343 | U8: 1098.3087 | W8: 1395.5691 | Y8: 1174.6714
A9: TVPROD0007 | B9: Sony 65" Full HD Smart LED TV with WebOS | C9: Sony | D9: TV | E9: 1011.15 | F9: 4.6 | G9: 2018 | H9: https://www.amazon.com/dp/TVPROD0007 | I9: Yes | J9: 65 | K9: Amazon | L9: yes | M9: Large | N9: =AVERAGEIF(C:C, C9, E:E) -> 1190.606 | O9: =E9 - N9 -> -179.45604 | P9: =IF(E9=_xlfn.MINIFS(E:E, B:B, B9), "Best Deal", "") -> Best Deal | S9: Small | T9: 321.24 | U9: 1084.855 | W9: 1245.7018 | Y9: 1103.3362
A10: TVPROD0008 | B10: Sony 60" 4K UHD Smart LED TV with Fire TV | C10: Sony | D10: TV | E10: 517.41 | F10: 4.3 | G10: 9728 | H10: https://www.amazon.com/dp/TVPROD0008 | I10: Yes | J10: 60 | K10: Amazon | L10: yes | M10: Large | N10: =AVERAGEIF(C:C, C10, E:E) -> 1190.606 | O10: =E10 - N10 -> -673.19604 | P10: =IF(E10=_xlfn.MINIFS(E:E, B:B, B10), "Best Deal", "") -> Best Deal | S10: Insignia | T10: 733.32533 | Y10: 733.32533
A11: TVPROD0009 | B11: Vizio 43" 4K UHD Smart LED TV with WebOS | C11: Vizio | D11: TV | E11: 549.88 | F11: 4.9 | G11: 2721 | H11: https://www.amazon.com/dp/TVPROD0009 | I11: No | J11: 43 | K11: Amazon | L11: no | M11: Medium | N11: =AVERAGEIF(C:C, C11, E:E) -> 1147.5588 | O11: =E11 - N11 -> -597.67883 | P11: =IF(E11=_xlfn.MINIFS(E:E, B:B, B11), "Best Deal", "") -> Best Deal | S11: Large | T11: 934.86571 | Y11: 934.86571
A12: TVPROD0010 | B12: Panasonic 50" HD Smart LED TV with Roku | C12: Panasonic | D12: TV | E12: 909.62 | F12: 4.2 | G12: 6031 | H12: https://www.amazon.com/dp/TVPROD0010 | I12: No | J12: 50 | K12: Amazon | L12: no | M12: Medium | N12: =AVERAGEIF(C:C, C12, E:E) -> 1094.8389 | O12: =E12 - N12 -> -185.21892 | P12: =IF(E12=_xlfn.MINIFS(E:E, B:B, B12), "Best Deal", "") -> Best Deal | S12: Medium | T12: 734.93375 | Y12: 734.93375
A13: TVPROD0011 | B13: LG 48" 8K UHD Smart LED TV with Fire TV | C13: LG | D13: TV | E13: 904.9 | F13: 4.4 | G13: 4151 | H13: https://www.amazon.com/dp/TVPROD0011 | I13: Yes | J13: 48 | K13: Amazon | L13: yes | M13: Medium | N13: =AVERAGEIF(C:C, C13, E:E) -> 1054.3238 | O13: =E13 - N13 -> -149.4238 | P13: =IF(E13=_xlfn.MINIFS(E:E, B:B, B13), "Best Deal", "") -> Best Deal | S13: Small | T13: 379.02125 | Y13: 379.02125
A14: TVPROD0012 | B14: LG 48" 8K UHD Smart LED TV with WebOS | C14: LG | D14: TV | E14: 483.1 | F14: 4.6 | G14: 2502 | H14: https://www.amazon.com/dp/TVPROD0012 | I14: Yes | J14: 48 | K14: Amazon | L14: yes | M14: Medium | N14: =AVERAGEIF(C:C, C14, E:E) -> 1054.3238 | O14: =E14 - N14 -> -571.2238 | P14: =IF(E14=_xlfn.MINIFS(E:E, B:B, B14), "Best Deal", "") -> Best Deal | S14: LG | T14: 638.68333 | U14: 1024.6432 | W14: 1217.1374 | Y14: 1054.3238
A15: TVPROD0013 | B15: Panasonic 40" 4K UHD Smart LED TV with WebOS | C15: Panasonic | D15: TV | E15: 244.86 | F15: 4.8 | G15: 5614 | H15: https://www.amazon.com/dp/TVPROD0013 | I15: Yes | J15: 40 | K15: Amazon | L15: yes | M15: Medium | N15: =AVERAGEIF(C:C, C15, E:E) -> 1094.8389 | O15: =E15 - N15 -> -849.97892 | P15: =IF(E15=_xlfn.MINIFS(E:E, B:B, B15), "Best Deal", "") -> Best Deal | S15: Large | T15: 826.22231 | U15: 1082.3562 | W15: 1211.5444 | Y15: 1120.3398
A16: TVPROD0014 | B16: Hisense 65" 8K UHD Smart LED TV with WebOS | C16: Hisense | D16: TV | E16: 692.52 | F16: 4.1 | G16: 4868 | H16: https://www.amazon.com/dp/TVPROD0014 | I16: Yes | J16: 65 | K16: Amazon | L16: yes | M16: Large | N16: =AVERAGEIF(C:C, C16, E:E) -> 1177.9799 | O16: =E16 - N16 -> -485.45994 | P16: =IF(E16=_xlfn.MINIFS(E:E, B:B, B16), "Best Deal", "") -> Best Deal | S16: Medium | T16: 673.307 | U16: 931.42958 | W16: 1089.2037 | Y16: 952.21155
A17: TVPROD0015 | B17: Philips 70" 4K UHD Smart LED TV with Android | C17: Philips | D17: TV | E17: 949.34 | F17: 4.4 | G17: 6602 | H17: https://www.amazon.com/dp/TVPROD0015 | I17: No | J17: 70 | K17: Amazon | L17: no | M17: Large | N17: =AVERAGEIF(C:C, C17, E:E) -> 1103.4574 | O17: =E17 - N17 -> -154.11743 | P17: =IF(E17=_xlfn.MINIFS(E:E, B:B, B17), "Best Deal", "") -> Best Deal | S17: Small | T17: 360.259 | U17: 1118.5517 | W17: 1415.5153 | Y17: 1041.7473
A18: TVPROD0016 | B18: Samsung 28" Full HD Smart LED TV with Tizen | C18: Samsung | D18: TV | E18: 524.87 | F18: 4.8 | G18: 6349 | H18: https://www.amazon.com/dp/TVPROD0016 | I18: No | J18: 28 | K18: Amazon | L18: no | M18: Small | N18: =AVERAGEIF(C:C, C18, E:E) -> 1136.2494 | O18: =E18 - N18 -> -611.37936 | P18: =IF(E18=_xlfn.MINIFS(E:E, B:B, B18), "Best Deal", "") -> Best Deal | S18: Panasonic | T18: 679.19741 | U18: 1020.1813 | W18: 1243.6864 | Y18: 1094.8389
A19: TVPROD0017 | B19: TCL 55" 8K UHD Smart LED TV with Fire TV | C19: TCL | D19: TV | E19: 650.34 | F19: 4.3 | G19: 2754 | H19: https://www.amazon.com/dp/TVPROD0017 | I19: No | J19: 55 | K19: Amazon | L19: no | M19: Medium | N19: =AVERAGEIF(C:C, C19, E:E) -> 1169.5641 | O19: =E19 - N19 -> -519.22406 | P19: =IF(E19=_xlfn.MINIFS(E:E, B:B, B19), "Best Deal", "") -> Best Deal | S19: Large | T19: 910.23125 | U19: 1005.4985 | W19: 1308.1216 | Y19: 1150.6401
A20: TVPROD0018 | B20: Sony 75" 4K UHD Smart LED TV with WebOS | C20: Sony | D20: TV | E20: 1400.93 | F20: 4.3 | G20: 2071 | H20: https://www.amazon.com/dp/TVPROD0018 | I20: No | J20: 75 | K20: Amazon | L20: no | M20: Large | N20: =AVERAGEIF(C:C, C20, E:E) -> 1190.606 | O20: =E20 - N20 -> 210.32396 | P20: =IF(E20=_xlfn.MINIFS(E:E, B:B, B20), "Best Deal", "") -> Best Deal | S20: Medium | T20: 634.51231 | U20: 940.25091 | W20: 1184.5505 | Y20: 1015.2926
A21: TVPROD0019 | B21: Insignia 50" HD Smart LED TV with WebOS | C21: Insignia | D21: TV | E21: 819.77 | F21: 4.8 | G21: 7604 | H21: https://www.amazon.com/dp/TVPROD0019 | I21: Yes | J21: 50 | K21: Amazon | L21: yes | M21: Medium | N21: =AVERAGEIF(C:C, C21, E:E) -> 733.32533 | O21: =E21 - N21 -> 86.444667 | P21: =IF(E21=_xlfn.MINIFS(E:E, B:B, B21), "Best Deal", "") -> Best Deal | S21: Small | T21: 467.97 | U21: 1610.2975 | W21: 1197.9135 | Y21: 1106.9093
A22: TVPROD0020 | B22: TCL 32" HD Smart LED TV with Tizen | C22: TCL | D22: TV | E22: 459.85 | F22: 4.9 | G22: 7340 | H22: https://www.amazon.com/dp/TVPROD0020 | I22: Yes | J22: 32 | K22: Amazon | L22: yes | M22: Small | N22: =AVERAGEIF(C:C, C22, E:E) -> 1169.5641 | O22: =E22 - N22 -> -709.71406 | P22: =IF(E22=_xlfn.MINIFS(E:E, B:B, B22), "Best Deal", "") -> Best Deal | S22: Philips | T22: 692.96233 | W22: 1219.6353 | Y22: 1103.4574
A23: TVPROD0021 | B23: TCL 75" HD Smart LED TV with Tizen | C23: TCL | D23: TV | E23: 1116.33 | F23: 4.3 | G23: 5133 | H23: https://www.amazon.com/dp/TVPROD0021 | I23: No | J23: 75 | K23: Amazon | L23: no | M23: Large | N23: =AVERAGEIF(C:C, C23, E:E) -> 1169.5641 | O23: =E23 - N23 -> -53.234059 | P23: =IF(E23=_xlfn.MINIFS(E:E, B:B, B23), "Best Deal", "") -> Best Deal | S23: Large | T23: 914.36667 | W23: 1242.5562 | Y23: 1191.4097
A24: TVPROD0022 | B24: Sharp 55" 8K UHD Smart LED TV with Fire TV | C24: Sharp | D24: TV | E24: 505.48 | F24: 4.8 | G24: 7520 | H24: https://www.amazon.com/dp/TVPROD0022 | I24: Yes | J24: 55 | K24: Amazon | L24: yes | M24: Medium | N24: =AVERAGEIF(C:C, C24, E:E) -> 1125.7376 | O24: =E24 - N24 -> -620.25765 | P24: =IF(E24=_xlfn.MINIFS(E:E, B:B, B24), "Best Deal", "") -> Best Deal | S24: Medium | T24: 564.48857 | W24: 1273.3503 | Y24: 1062.2
A25: TVPROD0023 | B25: Sony 58" HD Smart LED TV with Roku | C25: Sony | D25: TV | E25: 367.34 | F25: 4.9 | G25: 3870 | H25: https://www.amazon.com/dp/TVPROD0023 | I25: Yes | J25: 58 | K25: Amazon | L25: yes | M25: Large | N25: =AVERAGEIF(C:C, C25, E:E) -> 1190.606 | O25: =E25 - N25 -> -823.26604 | P25: =IF(E25=_xlfn.MINIFS(E:E, B:B, B25), "Best Deal", "") -> Best Deal | S25: Small | T25: 478.4075 | W25: 811.82875 | Y25: 700.68833
A26: TVPROD0024 | B26: Sharp 40" HD Smart LED TV with Roku | C26: Sharp | D26: TV | E26: 455.4 | F26: 4.8 | G26: 4391 | H26: https://www.amazon.com/dp/TVPROD0024 | I26: No | J26: 40 | K26: Amazon | L26: no | M26: Medium | N26: =AVERAGEIF(C:C, C26, E:E) -> 1125.7376 | O26: =E26 - N26 -> -670.33765 | P26: =IF(E26=_xlfn.MINIFS(E:E, B:B, B26), "Best Deal", "") -> Best Deal | S26: Samsung | T26: 725.477 | U26: 1001.4422 | V26: 1198.99 | W26: 1347.2587 | Y26: 1136.2494
A27: TVPROD0025 | B27: Sharp 75" Full HD Smart LED TV with WebOS | C27: Sharp | D27: TV | E27: 841.57 | F27: 4.8 | G27: 2049 | H27: https://www.amazon.com/dp/TVPROD0025 | I27: No | J27: 75 | K27: Amazon | L27: no | M27: Large | N27: =AVERAGEIF(C:C, C27, E:E) -> 1125.7376 | O27: =E27 - N27 -> -284.16765 | P27: =IF(E27=_xlfn.MINIFS(E:E, B:B, B27), "Best Deal", "") -> Best Deal | S27: Large | T27: 1091.808 | U27: 975.7968 | W27: 1330.6957 | Y27: 1206.9446
A28: TVPROD0026 | B28: Sony 28" 8K UHD Smart LED TV with WebOS | C28: Sony | D28: TV | E28: 615.06 | F28: 4.9 | G28: 6057 | H28: https://www.amazon.com/dp/TVPROD0026 | I28: Yes | J28: 28 | K28: Amazon | L28: yes | M28: Small | N28: =AVERAGEIF(C:C, C28, E:E) -> 1190.606 | O28: =E28 - N28 -> -575.54604 | P28: =IF(E28=_xlfn.MINIFS(E:E, B:B, B28), "Best Deal", "") | S28: Medium | T28: 661.064 | U28: 1205.2225 | V28: 999.99 | W28: 1371.4911 | Y28: 1145.9912
A29: TVPROD0027 | B29: Philips 75" Full HD Smart LED TV with WebOS | C29: Philips | D29: TV | E29: 570.81 | F29: 4.9 | G29: 3084 | H29: https://www.amazon.com/dp/TVPROD0027 | I29: No | J29: 75 | K29: Amazon | L29: no | M29: Large | N29: =AVERAGEIF(C:C, C29, E:E) -> 1103.4574 | O29: =E29 - N29 -> -532.64743 | P29: =IF(E29=_xlfn.MINIFS(E:E, B:B, B29), "Best Deal", "") -> Best Deal | S29: Small | T29: 423.559 | U29: 550.385 | V29: 1397.99 | W29: 1399.16 | Y29: 851.14833
A30: TVPROD0028 | B30: Sharp 60" HD Smart LED TV with WebOS | C30: Sharp | D30: TV | E30: 988.44 | F30: 4.8 | G30: 117 | H30: https://www.amazon.com/dp/TVPROD0028 | I30: No | J30: 60 | K30: Amazon | L30: no | M30: Large | N30: =AVERAGEIF(C:C, C30, E:E) -> 1125.7376 | O30: =E30 - N30 -> -137.29765 | P30: =IF(E30=_xlfn.MINIFS(E:E, B:B, B30), "Best Deal", "") -> Best Deal | S30: Sanyo | W30: 1275.1728 | Y30: 1275.1728
A31: TVPROD0029 | B31: Vizio 43" 4K UHD Smart LED TV with Fire TV | C31: Vizio | D31: TV | E31: 661.34 | F31: 4.2 | G31: 6612 | H31: https://www.amazon.com/dp/TVPROD0029 | I31: No | J31: 43 | K31: Amazon | L31: no | M31: Medium | N31: =AVERAGEIF(C:C, C31, E:E) -> 1147.5588 | O31: =E31 - N31 -> -486.21883 | P31: =IF(E31=_xlfn.MINIFS(E:E, B:B, B31), "Best Deal", "") -> Best Deal | S31: Large | W31: 1242.745 | Y31: 1242.745
A32: TVPROD0030 | B32: Insignia 70" 4K UHD Smart LED TV with Roku | C32: Insignia | D32: TV | E32: 973.55 | F32: 4.6 | G32: 425 | H32: https://www.amazon.com/dp/TVPROD0030 | I32: No | J32: 70 | K32: Amazon | L32: no | M32: Large | N32: =AVERAGEIF(C:C, C32, E:E) -> 733.32533 | O32: =E32 - N32 -> 240.22467 | P32: =IF(E32=_xlfn.MINIFS(E:E, B:B, B32), "Best Deal", "") -> Best Deal | S32: Medium | W32: 1298.9345 | Y32: 1298.9345
A33: TVPROD0031 | B33: Philips 32" HD Smart LED TV with Android | C33: Philips | D33: TV | E33: 406.59 | F33: 4.8 | G33: 9895 | H33: https://www.amazon.com/dp/TVPROD0031 | I33: Yes | J33: 32 | K33: Amazon | L33: yes | M33: Small | N33: =AVERAGEIF(C:C, C33, E:E) -> 1103.4574 | O33: =E33 - N33 -> -696.86743 | P33: =IF(E33=_xlfn.MINIFS(E:E, B:B, B33), "Best Deal", "") -> Best Deal | S33: Small | W33: 1354.9144 | Y33: 1354.9144
A34: TVPROD0032 | B34: Vizio 48" 8K UHD Smart LED TV with Tizen | C34: Vizio | D34: TV | E34: 1019.73 | F34: 4.8 | G34: 8403 | H34: https://www.amazon.com/dp/TVPROD0032 | I34: No | J34: 48 | K34: Amazon | L34: no | M34: Medium | N34: =AVERAGEIF(C:C, C34, E:E) -> 1147.5588 | O34: =E34 - N34 -> -127.82883 | P34: =IF(E34=_xlfn.MINIFS(E:E, B:B, B34), "Best Deal", "") -> Best Deal | S34: Sharp | T34: 723.35207 | U34: 912.015 | W34: 1317.7057 | Y34: 1125.7376
A35: TVPROD0033 | B35: LG 58" Full HD Smart LED TV with Android | C35: LG | D35: TV | E35: 373.44 | F35: 4.3 | G35: 3782 | H35: https://www.amazon.com/dp/TVPROD0033 | I35: Yes | J35: 58 | K35: Amazon | L35: yes | M35: Large | N35: =AVERAGEIF(C:C, C35, E:E) -> 1054.3238 | O35: =E35 - N35 -> -680.8838 | P35: =IF(E35=_xlfn.MINIFS(E:E, B:B, B35), "Best Deal", "") -> Best Deal | S35: Large | T35: 980.99 | U35: 983.6528 | W35: 1425.3515 | Y35: 1241.6969
A36: TVPROD0034 | B36: Vizio 48" 4K UHD Smart LED TV with Tizen | C36: Vizio | D36: TV | E36: 532.54 | F36: 4.3 | G36: 1804 | H36: https://www.amazon.com/dp/TVPROD0034 | I36: No | J36: 48 | K36: Amazon | L36: no | M36: Medium | N36: =AVERAGEIF(C:C, C36, E:E) -> 1147.5588 | O36: =E36 - N36 -> -615.01883 | P36: =IF(E36=_xlfn.MINIFS(E:E, B:B, B36), "Best Deal", "") -> Best Deal | S36: Medium | T36: 522.07222 | U36: 789.22471 | W36: 1223.3443 | Y36: 1015.8976
A37: TVPROD0035 | B37: Philips 24" Full HD Smart LED TV with Tizen | C37: Philips | D37: TV | E37: 491.73 | F37: 4.4 | G37: 5062 | H37: https://www.amazon.com/dp/TVPROD0035 | I37: No | J37: 24 | K37: Amazon | L37: no | M37: Small | N37: =AVERAGEIF(C:C, C37, E:E) -> 1103.4574 | O37: =E37 - N37 -> -611.72743 | P37: =IF(E37=_xlfn.MINIFS(E:E, B:B, B37), "Best Deal", "") -> Best Deal | S37: Small | T37: 424.11667 | U37: 986.1375 | W37: 1191.4671 | Y37: 990.52556
A38: TVPROD0036 | B38: Samsung 24" HD Smart LED TV with Android | C38: Samsung | D38: TV | E38: 412.99 | F38: 4.8 | G38: 1516 | H38: https://www.amazon.com/dp/TVPROD0036 | I38: No | J38: 24 | K38: Amazon | L38: no | M38: Small | N38: =AVERAGEIF(C:C, C38, E:E) -> 1136.2494 | O38: =E38 - N38 -> -723.25936 | P38: =IF(E38=_xlfn.MINIFS(E:E, B:B, B38), "Best Deal", "") -> Best Deal | S38: Sony | T38: 720.33276 | U38: 1069.886 | W38: 1387.4752 | Y38: 1190.606
A39: TVPROD0037 | B39: Insignia 60" Full HD Smart LED TV with WebOS | C39: Insignia | D39: TV | E39: 308.1 | F39: 4.3 | G39: 4331 | H39: https://www.amazon.com/dp/TVPROD0037 | I39: No | J39: 60 | K39: Amazon | L39: no | M39: Large | N39: =AVERAGEIF(C:C, C39, E:E) -> 733.32533 | O39: =E39 - N39 -> -425.22533 | P39: =IF(E39=_xlfn.MINIFS(E:E, B:B, B39), "Best Deal", "") -> Best Deal | S39: Large | T39: 890.01357 | U39: 1191.4393 | W39: 1452.5054 | Y39: 1295.4141
A40: TVPROD0038 | B40: TCL 60" 8K UHD Smart LED TV with Tizen | C40: TCL | D40: TV | E40: 848.85 | F40: 4.6 | G40: 4661 | H40: https://www.amazon.com/dp/TVPROD0038 | I40: No | J40: 60 | K40: Amazon | L40: no | M40: Large | N40: =AVERAGEIF(C:C, C40, E:E) -> 1169.5641 | O40: =E40 - N40 -> -320.71406 | P40: =IF(E40=_xlfn.MINIFS(E:E, B:B, B40), "Best Deal", "") -> Best Deal | S40: Medium | T40: 740.29 | U40: 924.49095 | W40: 1318.3373 | Y40: 1141.1784
...

Sheet Amazon
A1: product_id | B1: product_name | C1: product_brand | D1: category | E1: price | F1: rating | G1: rating_count | H1: product_link | I1: smart_feature | J1: screen_size_inch | K1: size_segment | L1: Smart_TV | M1: store
A2: TVPROD0000 | B2: Philips 43" 8K UHD Smart LED TV with Tizen | C2: Philips | D2: TV | E2: 320.17 | F2: 4.3 | G2: 1983 | H2: https://www.amazon.com/dp/TVPROD0000 | I2: No | J2: 43 | K2: Medium | L2: no | M2: Amazon
A3: TVPROD0001 | B3: Philips 48" 4K UHD Smart LED TV with Fire TV | C3: Philips | D3: TV | E3: 910.02 | F3: 4.5 | G3: 9568 | H3: https://www.amazon.com/dp/TVPROD0001 | I3: No | J3: 48 | K3: Medium | L3: no | M3: Amazon
A4: TVPROD0002 | B4: Vizio 40" HD Smart LED TV with Fire TV | C4: Vizio | D4: TV | E4: 632.41 | F4: 4.9 | G4: 692 | H4: https://www.amazon.com/dp/TVPROD0002 | I4: No | J4: 40 | K4: Medium | L4: no | M4: Amazon
A5: TVPROD0003 | B5: Insignia 70" Full HD Smart LED TV with Roku | C5: Insignia | D5: TV | E5: 839.65 | F5: 4.7 | G5: 4975 | H5: https://www.amazon.com/dp/TVPROD0003 | I5: No | J5: 70 | K5: Large | L5: no | M5: Amazon
A6: TVPROD0004 | B6: Samsung 55" 4K UHD Smart LED TV with Fire TV | C6: Samsung | D6: TV | E6: 1051.04 | F6: 4.2 | G6: 7315 | H6: https://www.amazon.com/dp/TVPROD0004 | I6: Yes | J6: 55 | K6: Medium | L6: yes | M6: Amazon
A7: TVPROD0005 | B7: Philips 85" 4K UHD Smart LED TV with WebOS | C7: Philips | D7: TV | E7: 1179.7 | F7: 4.4 | G7: 301 | H7: https://www.amazon.com/dp/TVPROD0005 | I7: Yes | J7: 85 | K7: Large | L7: yes | M7: Amazon
A8: TVPROD0006 | B8: Insignia 24" HD Smart LED TV with Roku | C8: Insignia | D8: TV | E8: 297.26 | F8: 4.3 | G8: 554 | H8: https://www.amazon.com/dp/TVPROD0006 | I8: Yes | J8: 24 | K8: Small | L8: yes | M8: Amazon
A9: TVPROD0007 | B9: Sony 65" Full HD Smart LED TV with WebOS | C9: Sony | D9: TV | E9: 1011.15 | F9: 4.6 | G9: 2018 | H9: https://www.amazon.com/dp/TVPROD0007 | I9: Yes | J9: 65 | K9: Large | L9: yes | M9: Amazon
A10: TVPROD0008 | B10: Sony 60" 4K UHD Smart LED TV with Fire TV | C10: Sony | D10: TV | E10: 517.41 | F10: 4.3 | G10: 9728 | H10: https://www.amazon.com/dp/TVPROD0008 | I10: Yes | J10: 60 | K10: Large | L10: yes | M10: Amazon
A11: TVPROD0009 | B11: Vizio 43" 4K UHD Smart LED TV with WebOS | C11: Vizio | D11: TV | E11: 549.88 | F11: 4.9 | G11: 2721 | H11: https://www.amazon.com/dp/TVPROD0009 | I11: No | J11: 43 | K11: Medium | L11: no | M11: Amazon
A12: TVPROD0010 | B12: Panasonic 50" HD Smart LED TV with Roku | C12: Panasonic | D12: TV | E12: 909.62 | F12: 4.2 | G12: 6031 | H12: https://www.amazon.com/dp/TVPROD0010 | I12: No | J12: 50 | K12: Medium | L12: no | M12: Amazon
A13: TVPROD0011 | B13: LG 48" 8K UHD Smart LED TV with Fire TV | C13: LG | D13: TV | E13: 904.9 | F13: 4.4 | G13: 4151 | H13: https://www.amazon.com/dp/TVPROD0011 | I13: Yes | J13: 48 | K13: Medium | L13: yes | M13: Amazon
... A301: TVPROD0299 | B301: Vizio 65" 4K UHD Smart LED TV with Android | C301: Vizio | D301: TV | E301: 970.93 | F301: 4.9 | G301: 4080 | H301: https://www.amazon.com/dp/TVPROD0299 | I301: No | J301: 65 | K301: Large | L301: no | M301: Amazon

Sheet Target
A1: product_id | B1: product_name | C1: product_brand | D1: category | E1: price | F1: rating | G1: rating_count | H1: product_link | I1: smart_feature | J1: screen_size_inch | K1: size_segment | L1: Smart_TV | M1: store
A2: 86314222 | B2: Samsung QN55QN85BA 55" Neo QLED 4K Smart TV (2022) | C2: Samsung | D2: TV | E2: 1397.99 | F2: 3.5 | G2: 100 | H2: https://www.target.com/p/samsung-qn55qn85ba-55-neo-qled-4k-smart-tv-2022/-/A-86314222 | I2: Yes | J2: 32 | K2: Small | L2: yes | M2: Target
A3: 86464021 | B3: Samsung QN50Q80BA 50" QLED 4K Smart TV (2022) | C3: Samsung | D3: TV | E3: 999.99 | F3: 3.6 | G3: 105 | H3: https://www.target.com/p/samsung-qn50q80ba-50-qled-4k-smart-tv-2022/-/A-86464021 | I3: Yes | J3: 40 | K3: Medium | L3: yes | M3: Target

Sheet Walmart
A1: product_id | B1: product_name | C1: product_brand | D1: category | E1: price | F1: rating | G1: rating_count | H1: product_link | I1: smart_feature | J1: screen_size_inch | K1: size_segment | L1: Smart_TV | M1: store
A2: TV1000 | B2: TCL 39 Inch UHD TV | C2: TCL | D2: Electronics > TV & Video > Smart TVs | E2: 1554.75 | F2: 4.18 | G2: 3884 | H2: https://www.walmart.com/ip/1000000 | I2: Yes | J2: 39 | K2: Small | L2: yes | M2: Walmart
A3: TV1001 | B3: Sharp 51 Inch OLED TV | C3: Sharp | D3: Electronics > TV & Video > Smart TVs | E3: 588.9 | F3: 4.01 | G3: 2027 | H3: https://www.walmart.com/ip/1000001 | I3: Yes | J3: 51 | K3: Medium | L3: yes | M3: Walmart
A4: TV1002 | B4: TCL 76 Inch 4K Smart TV | C4: TCL | D4: Electronics > TV & Video > Smart TVs | E4: 2122.41 | F4: 4.43 | G4: 6185 | H4: https://www.walmart.com/ip/1000002 | I4: Yes | J4: 76 | K4: Large | L4: yes | M4: Walmart
A5: TV1003 | B5: Sharp 45 Inch OLED TV | C5: Sharp | D5: Electronics > TV & Video > Smart TVs | E5: 2320.17 | F5: 4.17 | G5: 1193 | H5: https://www.walmart.com/ip/1000003 | I5: No | J5: 45 | K5: Medium | L5: no | M5: Walmart
A6: TV1004 | B6: Sharp 80 Inch OLED TV | C6: Sharp | D6: Electronics > TV & Video > Smart TVs | E6: 2091.28 | F6: 4.63 | G6: 2682 | H6: https://www.walmart.com/ip/1000004 | I6: Yes | J6: 80 | K6: Large | L6: yes | M6: Walmart
A7: TV1005 | B7: Samsung 65 Inch Android TV | C7: Samsung | D7: Electronics > TV & Video > Smart TVs | E7: 528.1 | F7: 4.47 | G7: 7135 | H7: https://www.walmart.com/ip/1000005 | I7: No | J7: 65 | K7: Large | L7: no | M7: Walmart
A8: TV1006 | B8: Vizio 51 Inch UHD TV | C8: Vizio | D8: Electronics > TV & Video > Smart TVs | E8: 370.62 | F8: 4.21 | G8: 4886 | H8: https://www.walmart.com/ip/1000006 | I8: No | J8: 51 | K8: Medium | L8: no | M8: Walmart
A9: TV1007 | B9: Sharp 81 Inch OLED TV | C9: Sharp | D9: Electronics > TV & Video > Smart TVs | E9: 1155.71 | F9: 4.77 | G9: 5105 | H9: https://www.walmart.com/ip/1000007 | I9: No | J9: 81 | K9: Large | L9: no | M9: Walmart
A10: TV1008 | B10: Sanyo 43 Inch Roku Smart TV | C10: Sanyo | D10: Electronics > TV & Video > Smart TVs | E10: 607.7 | F10: 4.27 | G10: 7442 | H10: https://www.walmart.com/ip/1000008 | I10: No | J10: 43 | K10: Medium | L10: no | M10: Walmart
A11: TV1009 | B11: Samsung 59 Inch 4K Smart TV | C11: Samsung | D11: Electronics > TV & Video > Smart TVs | E11: 1777.27 | F11: 4.08 | G11: 8795 | H11: https://www.walmart.com/ip/1000009 | I11: Yes | J11: 59 | K11: Large | L11: yes | M11: Walmart
A12: TV1010 | B12: Sony 42 Inch UHD TV | C12: Sony | D12: Electronics > TV & Video > Smart TVs | E12: 2173.38 | F12: 3.9 | G12: 8276 | H12: https://www.walmart.com/ip/1000010 | I12: No | J12: 42 | K12: Medium | L12: no | M12: Walmart
A13: TV1011 | B13: Sharp 81 Inch Android TV | C13: Sharp | D13: Electronics > TV & Video > Smart TVs | E13: 1407.8 | F13: 4.16 | G13: 6813 | H13: https://www.walmart.com/ip/1000011 | I13: No | J13: 81 | K13: Large | L13: no | M13: Walmart
... A1001: TV1999 | B1001: Vizio 50 Inch Roku Smart TV | C1001: Vizio | D1001: Electronics > TV & Video > Smart TVs | E1001: 1193.14 | F1001: 4.45 | G1001: 9079 | H1001: https://www.walmart.com/ip/1000999 | I1001: Yes | J1001: 50 | K1001: Medium | L1001: yes | M1001: Walmart

Sheet eBay
A1: product_id | B1: product_name | C1: product_brand | D1: category | E1: price | F1: rating | G1: rating_count | H1: product_link | I1: smart_feature | J1: screen_size_inch | K1: size_segment | L1: Smart_TV | M1: store
A2: c56ec6c8 | B2: Vizio 50" 4K Ultra HD TV | C2: Vizio | D2: TV | E2: 1195.15 | F2: 3.2 | G2: 729 | H2: https://www.ebay.com/itm/c56ec6c8 | I2: No | J2: 50 | K2: Medium | L2: no | M2: eBay
A3: 83f324f1 | B3: Samsung 58" 4K Ultra HD TV | C3: Samsung | D3: TV | E3: 581.98 | F3: 2.8 | G3: 714 | H3: https://www.ebay.com/itm/83f324f1 | I3: Yes | J3: 58 | K3: Large | L3: yes | M3: eBay
A4: 00faa83b | B4: LG 40" 4K Ultra HD TV | C4: LG | D4: TV | E4: 1863.65 | F4: 2.6 | G4: 414 | H4: https://www.ebay.com/itm/00faa83b | I4: No | J4: 40 | K4: Medium | L4: no | M4: eBay
A5: 1eea5044 | B5: Sony 40" 4K Ultra HD TV | C5: Sony | D5: TV | E5: 662.73 | F5: 3.7 | G5: 797 | H5: https://www.ebay.com/itm/1eea5044 | I5: Yes | J5: 40 | K5: Medium | L5: yes | M5: eBay
A6: 2760c776 | B6: Sharp 58" 4K Ultra HD TV | C6: Sharp | D6: TV | E6: 1764.46 | F6: 4 | G6: 1674 | H6: https://www.ebay.com/itm/2760c776 | I6: Yes | J6: 58 | K6: Large | L6: yes | M6: eBay
A7: 0e3cc1cf | B7: LG 50" 4K Ultra HD TV | C7: LG | D7: TV | E7: 637.36 | F7: 4.8 | G7: 1719 | H7: https://www.ebay.com/itm/0e3cc1cf | I7: No | J7: 50 | K7: Medium | L7: no | M7: eBay
A8: 6e4e1bdc | B8: LG 58" 4K Ultra HD TV | C8: LG | D8: TV | E8: 698.71 | F8: 3 | G8: 2805 | H8: https://www.ebay.com/itm/6e4e1bdc | I8: No | J8: 58 | K8: Large | L8: no | M8: eBay
A9: 6cd416a4 | B9: Sharp 43" 4K Ultra HD TV | C9: Sharp | D9: TV | E9: 373.02 | F9: 3.2 | G9: 1965 | H9: https://www.ebay.com/itm/6cd416a4 | I9: Yes | J9: 43 | K9: Medium | L9: yes | M9: eBay
A10: d8d74ce3 | B10: Sony 40" 4K Ultra HD TV | C10: Sony | D10: TV | E10: 1341.77 | F10: 3 | G10: 2312 | H10: https://www.ebay.com/itm/d8d74ce3 | I10: Yes | J10: 40 | K10: Medium | L10: yes | M10: eBay
A11: a6222906 | B11: Hisense 75" 4K Ultra HD TV | C11: Hisense | D11: TV | E11: 1022.53 | F11: 2.7 | G11: 2495 | H11: https://www.ebay.com/itm/a6222906 | I11: Yes | J11: 75 | K11: Large | L11: yes | M11: eBay
A12: 820c0b4b | B12: Sharp 50" 4K Ultra HD TV | C12: Sharp | D12: TV | E12: 1033.78 | F12: 2.7 | G12: 1052 | H12: https://www.ebay.com/itm/820c0b4b | I12: No | J12: 50 | K12: Medium | L12: no | M12: eBay
A13: 3f04b406 | B13: Samsung 50" 4K Ultra HD TV | C13: Samsung | D13: TV | E13: 1397.99 | F13: 4.9 | G13: 3718 | H13: https://www.ebay.com/itm/3f04b406 | I13: No | J13: 50 | K13: Medium | L13: no | M13: eBay
... A401: 5e12036c | B401: Panasonic 65" 4K Ultra HD TV | C401: Panasonic | D401: TV | E401: 208.94 | F401: 2.6 | G401: 2288 | H401: https://www.ebay.com/itm/5e12036c | I401: No | J401: 65 | K401: Large | L401: no | M401: eBay

Sheet Summary
A1: Store | B1: Average Price | C1: Average Screen Size | D1: Number of Smart TVs | E1: Total TVs
A2: Amazon | B2: =AVERAGEIFS(All_TVs!E:E, All_TVs!K:K, "Amazon") -> 724.77267 | C2: =AVERAGEIFS(All_TVs!J:J, All_TVs!K:K, "Amazon") -> 53.27 | D2: =COUNTIFS(All_TVs!L:L, "yes", All_TVs!K:K, "Amazon") -> 160 | E2: =COUNTIF(All_TVs!K:K, "Amazon") -> 300
A3: eBay | B3: =AVERAGEIFS(All_TVs!E:E, All_TVs!K:K, "eBay") -> 1023.8661 | C3: =AVERAGEIFS(All_TVs!J:J, All_TVs!K:K, "eBay") -> 57.89 | D3: =COUNTIFS(All_TVs!L:L, "yes", All_TVs!K:K, "eBay") -> 215 | E3: =COUNTIF(All_TVs!K:K, "eBay") -> 400
A4: Target | B4: =AVERAGEIFS(All_TVs!E:E, All_TVs!K:K, "Target") -> 1198.99 | C4: =AVERAGEIFS(All_TVs!J:J, All_TVs!K:K, "Target") -> 36 | D4: =COUNTIFS(All_TVs!L:L, "yes", All_TVs!K:K, "Target") -> 2 | E4: =COUNTIF(All_TVs!K:K, "Target") -> 2
A5: Walmart | B5: =AVERAGEIFS(All_TVs!E:E, All_TVs!K:K, "Walmart") -> 1299.7072 | C5: =AVERAGEIFS(All_TVs!J:J, All_TVs!K:K, "Walmart") -> 57.972 | D5: =COUNTIFS(All_TVs!L:L, "yes", All_TVs!K:K, "Walmart") -> 493 | E5: =COUNTIF(All_TVs!K:K, "Walmart") -> 1000
